
============================================================================
XAI Pipeline Batch Runner
============================================================================
[INFO] Configuration:
[INFO]   Modalities: vision
[INFO]   Datasets: stl10_resnet
[INFO]   Q Types: 1 2 3 4 5 6 7 8 9
[INFO]   Question IDs: 20 21 22 23 24
[INFO]   Use test variant: false
[INFO]   Dry run: false
[INFO]   No eval: false
[INFO]   No improvement: false
[INFO]   No strategy faithfulness: false
[INFO]   Faithfulness threshold: 0.1
[INFO]   Output dir: /standard/AikyamLab/yuyang/xai_agent/framework/trial_2/outputs

--- Building job list ---
[INFO] Job 1: stl10_resnet_q1_20
[INFO] Job 2: stl10_resnet_q1_21
[INFO] Job 3: stl10_resnet_q1_22
[INFO] Job 4: stl10_resnet_q1_23
[INFO] Job 5: stl10_resnet_q1_24
[INFO] Job 6: stl10_resnet_q2_20
[INFO] Job 7: stl10_resnet_q2_21
[INFO] Job 8: stl10_resnet_q2_22
[INFO] Job 9: stl10_resnet_q2_23
[INFO] Job 10: stl10_resnet_q2_24
[INFO] Job 11: stl10_resnet_q3_20
[INFO] Job 12: stl10_resnet_q3_21
[INFO] Job 13: stl10_resnet_q3_22
[INFO] Job 14: stl10_resnet_q3_23
[INFO] Job 15: stl10_resnet_q3_24
[INFO] Job 16: stl10_resnet_q4_20
[INFO] Job 17: stl10_resnet_q4_21
[INFO] Job 18: stl10_resnet_q4_22
[INFO] Job 19: stl10_resnet_q4_23
[INFO] Job 20: stl10_resnet_q4_24
[INFO] Job 21: stl10_resnet_q5_20
[INFO] Job 22: stl10_resnet_q5_21
[INFO] Job 23: stl10_resnet_q5_22
[INFO] Job 24: stl10_resnet_q5_23
[INFO] Job 25: stl10_resnet_q5_24
[INFO] Job 26: stl10_resnet_q6_20
[INFO] Job 27: stl10_resnet_q6_21
[INFO] Job 28: stl10_resnet_q6_22
[INFO] Job 29: stl10_resnet_q6_23
[INFO] Job 30: stl10_resnet_q6_24
[INFO] Job 31: stl10_resnet_q7_20
[INFO] Job 32: stl10_resnet_q7_21
[INFO] Job 33: stl10_resnet_q7_22
[INFO] Job 34: stl10_resnet_q7_23
[INFO] Job 35: stl10_resnet_q7_24
[INFO] Job 36: stl10_resnet_q8_20
[INFO] Job 37: stl10_resnet_q8_21
[INFO] Job 38: stl10_resnet_q8_22
[INFO] Job 39: stl10_resnet_q8_23
[INFO] Job 40: stl10_resnet_q8_24
[INFO] Job 41: stl10_resnet_q9_20
[INFO] Job 42: stl10_resnet_q9_21
[INFO] Job 43: stl10_resnet_q9_22
[INFO] Job 44: stl10_resnet_q9_23
[INFO] Job 45: stl10_resnet_q9_24

--- Job Summary ---
[INFO] Total jobs to run: 45

--- Executing jobs ---
[INFO] Logs will be saved to: /standard/AikyamLab/yuyang/xai_agent/framework/trial_2/outputs/logs/20260212_180028

--- Job 1 / 45 ---
[2026-02-12 18:00:28] Starting job 1
[2026-02-12 18:06:43] Job 1 FAILED

--- Job 2 / 45 ---
[2026-02-12 18:06:43] Starting job 2
[2026-02-12 18:13:37] Job 2 FAILED

--- Job 3 / 45 ---
[2026-02-12 18:13:37] Starting job 3
[2026-02-12 18:20:47] Job 3 FAILED

--- Job 4 / 45 ---
[2026-02-12 18:20:47] Starting job 4
[2026-02-12 18:27:24] Job 4 FAILED

--- Job 5 / 45 ---
[2026-02-12 18:27:24] Starting job 5
[2026-02-12 18:33:48] Job 5 FAILED

--- Job 6 / 45 ---
[2026-02-12 18:33:48] Starting job 6
[2026-02-12 18:35:38] Job 6 completed successfully

--- Job 7 / 45 ---
[2026-02-12 18:35:38] Starting job 7
[2026-02-12 18:43:37] Job 7 FAILED

--- Job 8 / 45 ---
[2026-02-12 18:43:37] Starting job 8
[2026-02-12 18:45:25] Job 8 completed successfully

--- Job 9 / 45 ---
[2026-02-12 18:45:25] Starting job 9
[2026-02-12 18:47:09] Job 9 completed successfully

--- Job 10 / 45 ---
[2026-02-12 18:47:09] Starting job 10
[2026-02-12 18:55:02] Job 10 FAILED

--- Job 11 / 45 ---
[2026-02-12 18:55:02] Starting job 11
[2026-02-12 19:03:06] Job 11 FAILED

--- Job 12 / 45 ---
[2026-02-12 19:03:06] Starting job 12
[2026-02-12 19:11:47] Job 12 FAILED

--- Job 13 / 45 ---
[2026-02-12 19:11:47] Starting job 13
[2026-02-12 19:19:28] Job 13 FAILED

--- Job 14 / 45 ---
[2026-02-12 19:19:28] Starting job 14
[2026-02-12 19:26:05] Job 14 FAILED

--- Job 15 / 45 ---
[2026-02-12 19:26:05] Starting job 15
[2026-02-12 19:34:53] Job 15 FAILED

--- Job 16 / 45 ---
[2026-02-12 19:34:53] Starting job 16
[2026-02-12 19:36:32] Job 16 completed successfully

--- Job 17 / 45 ---
[2026-02-12 19:36:32] Starting job 17
[2026-02-12 19:38:13] Job 17 completed successfully

--- Job 18 / 45 ---
[2026-02-12 19:38:13] Starting job 18
[2026-02-12 19:39:48] Job 18 completed successfully

--- Job 19 / 45 ---
[2026-02-12 19:39:48] Starting job 19
[2026-02-12 19:41:19] Job 19 completed successfully

--- Job 20 / 45 ---
[2026-02-12 19:41:19] Starting job 20
[2026-02-12 19:42:51] Job 20 completed successfully

--- Job 21 / 45 ---
[2026-02-12 19:42:51] Starting job 21
[2026-02-12 19:47:09] Job 21 completed successfully

--- Job 22 / 45 ---
[2026-02-12 19:47:09] Starting job 22
[2026-02-12 19:51:19] Job 22 completed successfully

--- Job 23 / 45 ---
[2026-02-12 19:51:19] Starting job 23
[2026-02-12 19:55:18] Job 23 completed successfully

--- Job 24 / 45 ---
[2026-02-12 19:55:18] Starting job 24
[2026-02-12 19:56:04] Job 24 completed successfully

--- Job 25 / 45 ---
[2026-02-12 19:56:04] Starting job 25
[2026-02-12 20:02:46] Job 25 FAILED

--- Job 26 / 45 ---
[2026-02-12 20:02:46] Starting job 26
[2026-02-12 20:13:50] Job 26 FAILED

--- Job 27 / 45 ---
[2026-02-12 20:13:50] Starting job 27
[2026-02-12 20:15:57] Job 27 completed successfully

--- Job 28 / 45 ---
[2026-02-12 20:15:57] Starting job 28
[2026-02-12 20:25:26] Job 28 FAILED

--- Job 29 / 45 ---
[2026-02-12 20:25:26] Starting job 29
[2026-02-12 20:34:16] Job 29 FAILED

--- Job 30 / 45 ---
[2026-02-12 20:34:16] Starting job 30
[2026-02-12 20:44:32] Job 30 FAILED

--- Job 31 / 45 ---
[2026-02-12 20:44:32] Starting job 31
[2026-02-12 20:52:19] Job 31 FAILED

--- Job 32 / 45 ---
[2026-02-12 20:52:19] Starting job 32
[2026-02-12 20:57:50] Job 32 FAILED

--- Job 33 / 45 ---
[2026-02-12 20:57:50] Starting job 33
[2026-02-12 20:58:16] Job 33 FAILED

--- Job 34 / 45 ---
[2026-02-12 20:58:16] Starting job 34
[2026-02-12 20:58:42] Job 34 FAILED

--- Job 35 / 45 ---
[2026-02-12 20:58:42] Starting job 35
[2026-02-12 20:59:08] Job 35 FAILED

--- Job 36 / 45 ---
[2026-02-12 20:59:08] Starting job 36
[2026-02-12 20:59:34] Job 36 FAILED

--- Job 37 / 45 ---
[2026-02-12 20:59:34] Starting job 37
[2026-02-12 21:00:00] Job 37 FAILED

--- Job 38 / 45 ---
[2026-02-12 21:00:00] Starting job 38
[2026-02-12 21:00:26] Job 38 FAILED

--- Job 39 / 45 ---
[2026-02-12 21:00:26] Starting job 39
[2026-02-12 21:00:53] Job 39 FAILED

--- Job 40 / 45 ---
[2026-02-12 21:00:53] Starting job 40
[2026-02-12 21:01:19] Job 40 FAILED

--- Job 41 / 45 ---
[2026-02-12 21:01:19] Starting job 41
[2026-02-12 21:01:57] Job 41 FAILED

--- Job 42 / 45 ---
[2026-02-12 21:01:57] Starting job 42
[2026-02-12 21:02:34] Job 42 FAILED

--- Job 43 / 45 ---
[2026-02-12 21:02:34] Starting job 43
[2026-02-12 21:03:11] Job 43 FAILED

--- Job 44 / 45 ---
[2026-02-12 21:03:11] Starting job 44
[2026-02-12 21:03:48] Job 44 FAILED

--- Job 45 / 45 ---
[2026-02-12 21:03:48] Starting job 45
[2026-02-12 21:04:25] Job 45 FAILED

============================================================================
Execution Summary
============================================================================
[INFO] Total jobs: 45
[INFO] Successful: 13
[INFO] Failed: 32
[INFO] Logs saved to: /standard/AikyamLab/yuyang/xai_agent/framework/trial_2/outputs/logs/20260212_180028
[WARN] Some jobs failed. Check logs for details.
/var/spool/slurm/slurmd/job8822309/slurm_script: line 29: --parallel: command not found
