
============================================================================
XAI Pipeline Batch Runner
============================================================================
[INFO] Configuration:
[INFO]   Modalities: vision
[INFO]   Datasets: stl10_densenet stl10_resnet cub_densenet cub_resnet
[INFO]   Mode: train
[INFO]   Q Types: 1 2 3 4 5 6 7 8 9 10
[INFO]   Question IDs: 0
[INFO]   Use test variant: false
[INFO]   Dry run: false
[INFO]   No eval: false
[INFO]   No improvement: false
[INFO]   No strategy faithfulness: false
[INFO]   Faithfulness threshold: 0.1
[INFO]   Output dir: /standard/AikyamLab/yuyang/xai_agent/framework/trial_2/outputs

--- Building job list ---
[INFO] Job 1: stl10_densenet_q1_0
[INFO] Job 2: stl10_densenet_q2_0
[INFO] Job 3: stl10_densenet_q3_0
[INFO] Job 4: stl10_densenet_q4_0
[INFO] Job 5: stl10_densenet_q5_0
[INFO] Job 6: stl10_densenet_q6_0
[INFO] Job 7: stl10_densenet_q7_0
[INFO] Job 8: stl10_densenet_q8_0
[INFO] Job 9: stl10_densenet_q9_0
[INFO] Job 10: stl10_densenet_q10_0
[INFO] Job 11: stl10_resnet_q1_0
[INFO] Job 12: stl10_resnet_q2_0
[INFO] Job 13: stl10_resnet_q3_0
[INFO] Job 14: stl10_resnet_q4_0
[INFO] Job 15: stl10_resnet_q5_0
[INFO] Job 16: stl10_resnet_q6_0
[INFO] Job 17: stl10_resnet_q7_0
[INFO] Job 18: stl10_resnet_q8_0
[INFO] Job 19: stl10_resnet_q9_0
[INFO] Job 20: stl10_resnet_q10_0
[INFO] Job 21: cub_densenet_q1_0
[INFO] Job 22: cub_densenet_q2_0
[INFO] Job 23: cub_densenet_q3_0
[INFO] Job 24: cub_densenet_q4_0
[INFO] Job 25: cub_densenet_q5_0
[INFO] Job 26: cub_densenet_q6_0
[INFO] Job 27: cub_densenet_q7_0
[INFO] Job 28: cub_densenet_q8_0
[INFO] Job 29: cub_densenet_q9_0
[INFO] Job 30: cub_densenet_q10_0
[INFO] Job 31: cub_resnet_q1_0
[INFO] Job 32: cub_resnet_q2_0
[INFO] Job 33: cub_resnet_q3_0
[INFO] Job 34: cub_resnet_q4_0
[INFO] Job 35: cub_resnet_q5_0
[INFO] Job 36: cub_resnet_q6_0
[INFO] Job 37: cub_resnet_q7_0
[INFO] Job 38: cub_resnet_q8_0
[INFO] Job 39: cub_resnet_q9_0
[INFO] Job 40: cub_resnet_q10_0

--- Job Summary ---
[INFO] Total jobs to run: 40

--- Executing jobs ---
[INFO] Logs will be saved to: /standard/AikyamLab/yuyang/xai_agent/framework/trial_2/outputs/logs/20260218_025727
[INFO] Running jobs in parallel (max 8 concurrent)
[2026-02-18 02:57:27] Starting job 1
[2026-02-18 02:57:27] Starting job 2
[2026-02-18 02:57:27] Starting job 3
[2026-02-18 02:57:27] Starting job 4
[2026-02-18 02:57:27] Starting job 5
[2026-02-18 02:57:27] Starting job 6
[2026-02-18 02:57:27] Starting job 7
[2026-02-18 02:57:27] Starting job 8
[2026-02-18 03:02:00] Job 3 FAILED
[2026-02-18 03:02:01] Job 7 FAILED
[2026-02-18 03:02:01] Starting job 10
[2026-02-18 03:02:02] Starting job 9
[2026-02-18 03:07:01] Job 2 completed successfully
[2026-02-18 03:07:01] Starting job 11
[2026-02-18 03:07:03] Job 10 completed successfully
[2026-02-18 03:07:03] Starting job 12
[2026-02-18 03:07:56] Job 1 FAILED
[2026-02-18 03:07:56] Starting job 13
[2026-02-18 03:09:16] Job 9 FAILED
[2026-02-18 03:09:17] Starting job 14
[2026-02-18 03:10:13] Job 5 FAILED
[2026-02-18 03:10:14] Starting job 15
[2026-02-18 03:10:24] Job 8 FAILED
[2026-02-18 03:10:25] Starting job 16
[2026-02-18 03:11:47] Job 13 FAILED
[2026-02-18 03:11:48] Starting job 17
[2026-02-18 03:11:52] Job 14 completed successfully
[2026-02-18 03:11:53] Starting job 18
[2026-02-18 03:12:12] Job 12 completed successfully
[2026-02-18 03:12:13] Starting job 19
[2026-02-18 03:13:38] Job 4 completed successfully
[2026-02-18 03:13:39] Starting job 20
[2026-02-18 03:13:56] Job 15 FAILED
[2026-02-18 03:13:56] Starting job 21
[2026-02-18 03:15:03] Job 6 FAILED
[2026-02-18 03:15:04] Starting job 22
[2026-02-18 03:15:12] Job 16 completed successfully
[2026-02-18 03:15:13] Starting job 23
[2026-02-18 03:15:31] Job 11 FAILED
[2026-02-18 03:15:31] Starting job 24
[2026-02-18 03:15:33] Job 18 FAILED
[2026-02-18 03:15:34] Starting job 25
[2026-02-18 03:15:49] Job 17 FAILED
[2026-02-18 03:15:50] Starting job 26
[2026-02-18 03:15:52] Job 24 FAILED
[2026-02-18 03:15:52] Starting job 27
[2026-02-18 03:16:12] Job 22 completed successfully
[2026-02-18 03:16:13] Starting job 28
[2026-02-18 03:16:44] Job 27 completed successfully
[2026-02-18 03:16:45] Starting job 29
[2026-02-18 03:16:48] Job 26 completed successfully
[2026-02-18 03:16:49] Starting job 30
[2026-02-18 03:16:58] Job 20 completed successfully
[2026-02-18 03:16:59] Starting job 31
[2026-02-18 03:18:12] Job 31 completed successfully
[2026-02-18 03:18:13] Job 21 completed successfully
[2026-02-18 03:18:13] Starting job 33
[2026-02-18 03:18:13] Starting job 32
[2026-02-18 03:18:28] Job 23 FAILED
[2026-02-18 03:18:29] Starting job 34
[2026-02-18 03:18:55] Job 34 FAILED
[2026-02-18 03:18:55] Starting job 35
[2026-02-18 03:19:02] Job 30 completed successfully
[2026-02-18 03:19:03] Starting job 36
[2026-02-18 03:20:07] Job 19 FAILED
[2026-02-18 03:20:07] Starting job 37
[2026-02-18 03:22:14] Job 33 FAILED
[2026-02-18 03:22:14] Starting job 38
[2026-02-18 03:22:38] Job 32 FAILED
[2026-02-18 03:22:38] Starting job 39
[2026-02-18 03:23:07] Job 25 FAILED
[2026-02-18 03:23:08] Starting job 40
[2026-02-18 03:23:29] Job 29 FAILED
[2026-02-18 03:24:38] Job 28 FAILED
[2026-02-18 03:25:50] Job 40 completed successfully
[2026-02-18 03:25:50] Job 36 completed successfully
[2026-02-18 03:26:41] Job 38 completed successfully
[2026-02-18 03:27:21] Job 35 FAILED
[2026-02-18 03:28:19] Job 37 FAILED
[2026-02-18 03:29:14] Job 39 FAILED

============================================================================
Execution Summary
============================================================================
[INFO] Total jobs: 40
[INFO] Successful: 0
[INFO] Failed: 0
[INFO] Logs saved to: /standard/AikyamLab/yuyang/xai_agent/framework/trial_2/outputs/logs/20260218_025727

Done!
