
============================================================================
XAI Pipeline Batch Runner
============================================================================
[INFO] Configuration:
[INFO]   Modalities: vision
[INFO]   Datasets: adult_tabnn adult_2layernn cancer_tabnn cancer_2layernn
[INFO]   Mode: train
[INFO]   Q Types: 1 2 3 4 5 6 7 8 9 10
[INFO]   Question IDs: 0
[INFO]   Use test variant: false
[INFO]   Dry run: false
[INFO]   No eval: false
[INFO]   No improvement: false
[INFO]   No strategy faithfulness: false
[INFO]   Faithfulness threshold: 0.1
[INFO]   Output dir: /standard/AikyamLab/yuyang/xai_agent/framework/trial_2/outputs

--- Building job list ---
[INFO] Job 1: adult_tabnn_q1_0
[INFO] Job 2: adult_tabnn_q2_0
[INFO] Job 3: adult_tabnn_q3_0
[INFO] Job 4: adult_tabnn_q4_0
[INFO] Job 5: adult_tabnn_q5_0
[INFO] Job 6: adult_tabnn_q6_0
[INFO] Job 7: adult_tabnn_q7_0
[INFO] Job 8: adult_tabnn_q8_0
[INFO] Job 9: adult_tabnn_q9_0
[INFO] Job 10: adult_tabnn_q10_0
[INFO] Job 11: adult_2layernn_q1_0
[INFO] Job 12: adult_2layernn_q2_0
[INFO] Job 13: adult_2layernn_q3_0
[INFO] Job 14: adult_2layernn_q4_0
[INFO] Job 15: adult_2layernn_q5_0
[INFO] Job 16: adult_2layernn_q6_0
[INFO] Job 17: adult_2layernn_q7_0
[INFO] Job 18: adult_2layernn_q8_0
[INFO] Job 19: adult_2layernn_q9_0
[INFO] Job 20: adult_2layernn_q10_0
[INFO] Job 21: cancer_tabnn_q1_0
[INFO] Job 22: cancer_tabnn_q2_0
[INFO] Job 23: cancer_tabnn_q3_0
[INFO] Job 24: cancer_tabnn_q4_0
[INFO] Job 25: cancer_tabnn_q5_0
[INFO] Job 26: cancer_tabnn_q6_0
[INFO] Job 27: cancer_tabnn_q7_0
[INFO] Job 28: cancer_tabnn_q8_0
[INFO] Job 29: cancer_tabnn_q9_0
[INFO] Job 30: cancer_tabnn_q10_0
[INFO] Job 31: cancer_2layernn_q1_0
[INFO] Job 32: cancer_2layernn_q2_0
[INFO] Job 33: cancer_2layernn_q3_0
[INFO] Job 34: cancer_2layernn_q4_0
[INFO] Job 35: cancer_2layernn_q5_0
[INFO] Job 36: cancer_2layernn_q6_0
[INFO] Job 37: cancer_2layernn_q7_0
[INFO] Job 38: cancer_2layernn_q8_0
[INFO] Job 39: cancer_2layernn_q9_0
[INFO] Job 40: cancer_2layernn_q10_0

--- Job Summary ---
[INFO] Total jobs to run: 40

--- Executing jobs ---
[INFO] Logs will be saved to: /standard/AikyamLab/yuyang/xai_agent/framework/trial_2/outputs/logs/20260218_022420
[INFO] Running jobs in parallel (max 8 concurrent)
[2026-02-18 02:24:20] Starting job 1
[2026-02-18 02:24:20] Starting job 2
[2026-02-18 02:24:20] Starting job 3
[2026-02-18 02:24:20] Starting job 4
[2026-02-18 02:24:20] Starting job 5
[2026-02-18 02:24:20] Starting job 6
[2026-02-18 02:24:21] Starting job 7
[2026-02-18 02:24:21] Starting job 8
[2026-02-18 02:25:05] Job 4 completed successfully
[2026-02-18 02:25:05] Starting job 9
[2026-02-18 02:25:11] Job 2 completed successfully
[2026-02-18 02:25:11] Starting job 10
[2026-02-18 02:25:43] Job 1 FAILED
[2026-02-18 02:25:43] Starting job 11
[2026-02-18 02:26:26] Job 7 FAILED
[2026-02-18 02:26:27] Starting job 12
[2026-02-18 02:26:32] Job 11 FAILED
[2026-02-18 02:26:33] Starting job 13
[2026-02-18 02:26:42] Job 5 FAILED
[2026-02-18 02:26:42] Starting job 14
[2026-02-18 02:26:50] Job 3 FAILED
[2026-02-18 02:26:50] Starting job 15
[2026-02-18 02:27:01] Job 12 completed successfully
[2026-02-18 02:27:01] Starting job 16
[2026-02-18 02:27:12] Job 6 FAILED
[2026-02-18 02:27:12] Starting job 17
[2026-02-18 02:27:13] Job 8 FAILED
[2026-02-18 02:27:14] Starting job 18
[2026-02-18 02:27:22] Job 14 completed successfully
[2026-02-18 02:27:22] Starting job 19
[2026-02-18 02:27:43] Job 16 completed successfully
[2026-02-18 02:27:43] Starting job 20
[2026-02-18 02:27:49] Job 17 completed successfully
[2026-02-18 02:27:50] Starting job 21
[2026-02-18 02:28:12] Job 13 FAILED
[2026-02-18 02:28:13] Starting job 22
[2026-02-18 02:28:20] Job 9 FAILED
[2026-02-18 02:28:20] Starting job 23
[2026-02-18 02:28:38] Job 21 FAILED
[2026-02-18 02:28:39] Starting job 24
[2026-02-18 02:28:50] Job 10 FAILED
[2026-02-18 02:28:51] Starting job 25
[2026-02-18 02:28:55] Job 22 completed successfully
[2026-02-18 02:28:55] Starting job 26
[2026-02-18 02:29:01] Job 25 FAILED
[2026-02-18 02:29:01] Starting job 27
[2026-02-18 02:29:04] Job 15 FAILED
[2026-02-18 02:29:04] Starting job 28
[2026-02-18 02:29:19] Job 24 completed successfully
[2026-02-18 02:29:20] Starting job 29
[2026-02-18 02:29:34] Job 26 completed successfully
[2026-02-18 02:29:35] Starting job 30
[2026-02-18 02:29:39] Job 23 FAILED
[2026-02-18 02:29:40] Starting job 31
[2026-02-18 02:29:45] Job 18 FAILED
[2026-02-18 02:29:46] Starting job 32
[2026-02-18 02:30:23] Job 32 completed successfully
[2026-02-18 02:30:23] Starting job 33
[2026-02-18 02:30:35] Job 19 FAILED
[2026-02-18 02:30:36] Starting job 34
[2026-02-18 02:30:39] Job 28 FAILED
[2026-02-18 02:30:39] Starting job 35
[2026-02-18 02:30:49] Job 35 FAILED
[2026-02-18 02:30:50] Starting job 36
[2026-02-18 02:31:00] Job 31 FAILED
[2026-02-18 02:31:01] Starting job 37
[2026-02-18 02:31:16] Job 34 completed successfully
[2026-02-18 02:31:16] Starting job 38
[2026-02-18 02:31:22] Job 20 FAILED
[2026-02-18 02:31:23] Starting job 39
[2026-02-18 02:31:32] Job 27 FAILED
[2026-02-18 02:31:33] Starting job 40
[2026-02-18 02:31:43] Job 37 completed successfully
[2026-02-18 02:31:43] Job 36 FAILED
[2026-02-18 02:31:43] Job 33 FAILED
[2026-02-18 02:32:05] Job 38 completed successfully
[2026-02-18 02:33:23] Job 29 FAILED
[2026-02-18 02:33:44] Job 30 FAILED
[2026-02-18 02:35:01] Job 39 FAILED
[2026-02-18 02:35:08] Job 40 FAILED

============================================================================
Execution Summary
============================================================================
[INFO] Total jobs: 40
[INFO] Successful: 0
[INFO] Failed: 0
[INFO] Logs saved to: /standard/AikyamLab/yuyang/xai_agent/framework/trial_2/outputs/logs/20260218_022420

Done!
